<?xml version="1.0" encoding="utf-8"?>
<robot name="fatu">

    <material name="dark_gray"><color rgba="0.3 0.3 0.3 1.0"/></material>
    <material name="silver"><color rgba="0.75 0.75 0.75 1.0"/></material>

    <link name="base_link">
        <inertial>
            <origin xyz="0.026103 0.000278 0.024686" rpy="0 0 0" />
            <mass value="9.016326" />
            <inertia ixx="0.060632" ixy="-0.0002" ixz="-0.033265" iyy="0.144345" iyz="-0.000044" izz="0.125819" />
        </inertial>
        <visual>
            <geometry><mesh filename="package://meshes/base_link.STL" /></geometry>
            <material name="silver"/>
        </visual>
        <collision>
            <origin xyz="0 0 0.004583" />
            <geometry><box size="0.133329 0.101205 0.068913" /></geometry>
        </collision>
    </link>

    <link name="trunk_imu">
        <inertial>
            <origin xyz="0 0 0" rpy="0 0 0" />
            <mass value="0" />
            <inertia ixx="0" ixy="0" ixz="0" iyy="0" iyz="0" izz="0" />
        </inertial>
    </link>
    <joint name="trunk_imu_joint" type="fixed">
        <parent link="base_link"/>
        <child link="trunk_imu"/>
        <origin xyz="0 0 0" rpy="0 0 0"/>
    </joint>

    <link name="FR_hip">
        <inertial>
            <origin xyz="-0.027882 0.015355 0" />
            <mass value="0.079643" />
            <inertia ixx="8.72e-05" ixy="0" ixz="0" iyy="7.78e-05" iyz="0" izz="2.29e-05" />
        </inertial>
        <visual>
            <geometry><mesh filename="package://meshes/FR_hip.STL" /></geometry>
        </visual>
        <collision>
            <origin xyz="0 -0.08 0" rpy="1.5707963267948966 0 0"/>
            <geometry><cylinder length="0.04" radius="0.046"/></geometry>
        </collision>
    </link>

    <joint name="FR_hip_joint" type="revolute">
        <origin xyz="0.18453 -0.051 0" rpy="0 0 0" />
        <parent link="base_link" />
        <child link="FR_hip" />
        <axis xyz="1 0 0" />
        <limit lower="-0.733" upper="0.733" effort="12" velocity="10" />
        <dynamics damping="0.1" friction="0.2"/>
    </joint>

    <link name="FR_thigh">
        <inertial>
            <origin xyz="-0.000498 0.038065 -0.024467" />
            <mass value="1.55038" />
            <inertia ixx="0.00679" ixy="0" ixz="0" iyy="0.00587" iyz="0" izz="0.00204" />
        </inertial>
        <visual>
            <geometry><mesh filename="package://meshes/FR_thigh.STL" /></geometry>
        </visual>
        <collision>
            <origin xyz="0 0 -0.103" rpy="0 0 0"/>
            <geometry><box size="0.06 0.08 0.2"/></geometry>
        </collision>
    </link>

    <joint name="FR_thigh_joint" type="revolute">
        <origin xyz="0 -0.0975 0" rpy="0 0 0" />
        <parent link="FR_hip" />
        <child link="FR_thigh" />
        <axis xyz="0 1 0" />
        <limit lower="-1.559" upper="3.129" effort="12" velocity="10" />
        <dynamics damping="0.1" friction="0.2"/>
    </joint>

    <link name="FR_calf">
        <inertial>
            <origin xyz="0.002616 0 -0.1253" />
            <mass value="0.183986" />
            <inertia ixx="0.00125" ixy="0" ixz="0" iyy="0.00123" iyz="0" izz="3.55e-05" />
        </inertial>
        <visual>
            <geometry><mesh filename="package://meshes/FR_calf.STL" /></geometry>
        </visual>
        <collision>
            <origin xyz="0 0 -0.1" rpy="0 0 0"/>
            <geometry><box size="0.02 0.02 0.2"/></geometry>
        </collision>
    </link>

    <joint name="FR_calf_joint" type="revolute">
        <origin xyz="0 0 -0.1985" rpy="0 0 0" />
        <parent link="FR_thigh" />
        <child link="FR_calf" />
        <axis xyz="0 1 0" />
        <limit lower="-2.638" upper="-0.785" effort="24" velocity="10" />
        <dynamics damping="0.1" friction="0.2"/>
    </joint>

    <link name="FR_foot">
        <inertial>
            <origin xyz="0 0 0" rpy="0 0 0" />
            <mass value="0.01"/>
            <inertia ixx="1e-5" ixy="0" ixz="0" iyy="1e-5" iyz="0" izz="1e-5"/>
        </inertial>
        <visual>
            <geometry><mesh filename="package://meshes/FR_foot.STL" /></geometry>
        </visual>
        <collision>
            <origin xyz="0 0 0" rpy="0 0 0"/>
            <geometry><sphere radius="0.021"/></geometry>
        </collision>
    </link>
    <joint name="FR_foot_joint" type="fixed" dont_collapse="true">
        <origin xyz="0 0 -0.214" rpy="0 0 0" />
        <parent link="FR_calf" />
        <child link="FR_foot" />
    </joint>


    <link name="FL_hip">
        <inertial>
            <origin xyz="-0.027882 -0.015355 0" />
            <mass value="0.079643" />
            <inertia ixx="8.72e-05" ixy="0" ixz="0" iyy="7.78e-05" iyz="0" izz="2.29e-05" />
        </inertial>
        <visual>
            <geometry><mesh filename="package://meshes/FL_hip.STL" /></geometry>
        </visual>
        <collision>
            <origin xyz="0 0.08 0" rpy="1.5707963267948966 0 0"/>
            <geometry><cylinder length="0.04" radius="0.046"/></geometry>
        </collision>
    </link>

    <joint name="FL_hip_joint" type="revolute">
        <origin xyz="0.18453 0.051 0" rpy="0 0 0" />
        <parent link="base_link" />
        <child link="FL_hip" />
        <axis xyz="1 0 0" />
        <limit lower="-0.733" upper="0.733" effort="12" velocity="10" />
        <dynamics damping="0.1" friction="0.2"/>
    </joint>

    <link name="FL_thigh">
        <inertial>
            <origin xyz="-0.000498 -0.038065 -0.024467" />
            <mass value="1.55038" />
            <inertia ixx="0.00679" ixy="0" ixz="0" iyy="0.00587" iyz="0" izz="0.00204" />
        </inertial>
        <visual>
            <geometry><mesh filename="package://meshes/FL_thigh.STL" /></geometry>
        </visual>
        <collision>
            <origin xyz="0 0 -0.103" rpy="0 0 0"/>
            <geometry><box size="0.06 0.08 0.2"/></geometry>
        </collision>
    </link>

    <joint name="FL_thigh_joint" type="revolute">
        <origin xyz="0 0.0975 0" rpy="0 0 0" />
        <parent link="FL_hip" />
        <child link="FL_thigh" />
        <axis xyz="0 1 0" />
        <limit lower="-1.559" upper="3.129" effort="12" velocity="10" />
        <dynamics damping="0.1" friction="0.2"/>
    </joint>

    <link name="FL_calf">
        <inertial>
            <origin xyz="0.002616 0 -0.1253" />
            <mass value="0.183986" />
            <inertia ixx="0.00125" ixy="0" ixz="0" iyy="0.00123" iyz="0" izz="3.55e-05" />
        </inertial>
        <visual>
            <geometry><mesh filename="package://meshes/FL_calf.STL" /></geometry>
        </visual>
        <collision>
            <origin xyz="0 0 -0.1" rpy="0 0 0"/>
            <geometry><box size="0.02 0.02 0.2"/></geometry>
        </collision>
    </link>

    <joint name="FL_calf_joint" type="revolute">
        <origin xyz="0 0 -0.1985" rpy="0 0 0" />
        <parent link="FL_thigh" />
        <child link="FL_calf" />
        <axis xyz="0 1 0" />
        <limit lower="-2.638" upper="-0.785" effort="24" velocity="10" />
        <dynamics damping="0.1" friction="0.2"/>
    </joint>

    <link name="FL_foot">
        <inertial>
            <origin xyz="0 0 0" rpy="0 0 0" />
            <mass value="0.01"/>
            <inertia ixx="1e-5" ixy="0" ixz="0" iyy="1e-5" iyz="0" izz="1e-5"/>
        </inertial>
        <visual>
            <geometry><mesh filename="package://meshes/FL_foot.STL" /></geometry>
        </visual>
        <collision>
            <origin xyz="0 0 0" rpy="0 0 0"/>
            <geometry><sphere radius="0.021"/></geometry>
        </collision>
    </link>
    <joint name="FL_foot_joint" type="fixed" dont_collapse="true">
        <origin xyz="0 0 -0.214" rpy="0 0 0" />
        <parent link="FL_calf" />
        <child link="FL_foot" />
    </joint>


    <link name="RR_hip">
        <inertial>
            <origin xyz="0.027882 0.015355 0" />
            <mass value="0.079643" />
            <inertia ixx="8.72e-05" ixy="0" ixz="0" iyy="7.78e-05" iyz="0" izz="2.29e-05" />
        </inertial>
        <visual>
            <geometry><mesh filename="package://meshes/RR_hip.STL" /></geometry>
        </visual>
        <collision>
            <origin xyz="0 -0.08 0" rpy="1.5707963267948966 0 0"/>
            <geometry><cylinder length="0.04" radius="0.046"/></geometry>
        </collision>
    </link>

    <joint name="RR_hip_joint" type="revolute">
        <origin xyz="-0.18453 -0.051 0" rpy="0 0 0" />
        <parent link="base_link" />
        <child link="RR_hip" />
        <axis xyz="1 0 0" />
        <limit lower="-0.733" upper="0.733" effort="12" velocity="10" />
        <dynamics damping="0.1" friction="0.2"/>
    </joint>

    <link name="RR_thigh">
        <inertial>
            <origin xyz="-0.000498 0.038065 -0.024467" />
            <mass value="1.55038" />
            <inertia ixx="0.00679" ixy="0" ixz="0" iyy="0.00587" iyz="0" izz="0.00204" />
        </inertial>
        <visual>
            <geometry><mesh filename="package://meshes/RR_thigh.STL" /></geometry>
        </visual>
        <collision>
            <origin xyz="0 0 -0.103" rpy="0 0 0"/>
            <geometry><box size="0.06 0.08 0.2"/></geometry>
        </collision>
    </link>

    <joint name="RR_thigh_joint" type="revolute">
        <origin xyz="0 -0.0975 0" rpy="0 0 0" />
        <parent link="RR_hip" />
        <child link="RR_thigh" />
        <axis xyz="0 1 0" />
        <limit lower="-0.512" upper="4.177" effort="12" velocity="10" />
        <dynamics damping="0.1" friction="0.2"/>
    </joint>

    <link name="RR_calf">
        <inertial>
            <origin xyz="0.002616 0 -0.1253" />
            <mass value="0.183986" />
            <inertia ixx="0.00125" ixy="0" ixz="0" iyy="0.00123" iyz="0" izz="3.55e-05" />
        </inertial>
        <visual>
            <geometry><mesh filename="package://meshes/RR_calf.STL" /></geometry>
        </visual>
        <collision>
            <origin xyz="0 0 -0.1" rpy="0 0 0"/>
            <geometry><box size="0.02 0.02 0.2"/></geometry>
        </collision>
    </link>

    <joint name="RR_calf_joint" type="revolute">
        <origin xyz="0 0 -0.1985" rpy="0 0 0" />
        <parent link="RR_thigh" />
        <child link="RR_calf" />
        <axis xyz="0 1 0" />
        <limit lower="-2.638" upper="-0.785" effort="24" velocity="10" />
        <dynamics damping="0.1" friction="0.2"/>
    </joint>

    <link name="RR_foot">
        <inertial>
            <origin xyz="0 0 0" rpy="0 0 0" />
            <mass value="0.01"/>
            <inertia ixx="1e-5" ixy="0" ixz="0" iyy="1e-5" iyz="0" izz="1e-5"/>
        </inertial>
        <visual>
            <geometry><mesh filename="package://meshes/RR_foot.STL" /></geometry>
        </visual>
        <collision>
            <origin xyz="0 0 0" rpy="0 0 0"/>
            <geometry><sphere radius="0.021"/></geometry>
        </collision>
    </link>
    <joint name="RR_foot_joint" type="fixed" dont_collapse="true">
        <origin xyz="0 0 -0.214" rpy="0 0 0" />
        <parent link="RR_calf" />
        <child link="RR_foot" />
    </joint>


    <link name="RL_hip">
        <inertial>
            <origin xyz="0.027882 -0.015355 0" />
            <mass value="0.079643" />
            <inertia ixx="8.72e-05" ixy="0" ixz="0" iyy="7.78e-05" iyz="0" izz="2.29e-05" />
        </inertial>
        <visual>
            <geometry><mesh filename="package://meshes/RL_hip.STL" /></geometry>
        </visual>
        <collision>
            <origin xyz="0 0.08 0" rpy="1.5707963267948966 0 0"/>
            <geometry><cylinder length="0.04" radius="0.046"/></geometry>
        </collision>
    </link>

    <joint name="RL_hip_joint" type="revolute">
        <origin xyz="-0.18453 0.051 0" rpy="0 0 0" />
        <parent link="base_link" />
        <child link="RL_hip" />
        <axis xyz="1 0 0" />
        <limit lower="-0.733" upper="0.733" effort="12" velocity="10" />
        <dynamics damping="0.1" friction="0.2"/>
    </joint>

    <link name="RL_thigh">
        <inertial>
            <origin xyz="-0.000498 -0.038065 -0.024467" />
            <mass value="1.55038" />
            <inertia ixx="0.00679" ixy="0" ixz="0" iyy="0.00587" iyz="0" izz="0.00204" />
        </inertial>
        <visual>
            <geometry><mesh filename="package://meshes/RL_thigh.STL" /></geometry>
        </visual>
        <collision>
            <origin xyz="0 0 -0.103" rpy="0 0 0"/>
            <geometry><box size="0.06 0.08 0.2"/></geometry>
        </collision>
    </link>

    <joint name="RL_thigh_joint" type="revolute">
        <origin xyz="0 0.0975 0" rpy="0 0 0" />
        <parent link="RL_hip" />
        <child link="RL_thigh" />
        <axis xyz="0 1 0" />
        <limit lower="-0.512" upper="4.177" effort="12" velocity="10" />
        <dynamics damping="0.1" friction="0.2"/>
    </joint>

    <link name="RL_calf">
        <inertial>
            <origin xyz="0.002616 0 -0.1253" />
            <mass value="0.183986" />
            <inertia ixx="0.00125" ixy="0" ixz="0" iyy="0.00123" iyz="0" izz="3.55e-05" />
        </inertial>
        <visual>
            <geometry><mesh filename="package://meshes/RL_calf.STL" /></geometry>
        </visual>
        <collision>
            <origin xyz="0 0 -0.1" rpy="0 0 0"/>
            <geometry><box size="0.02 0.02 0.2"/></geometry>
        </collision>
    </link>

    <joint name="RL_calf_joint" type="revolute">
        <origin xyz="0 0 -0.1985" rpy="0 0 0" />
        <parent link="RL_thigh" />
        <child link="RL_calf" />
        <axis xyz="0 1 0" />
        <limit lower="-2.638" upper="-0.785" effort="24" velocity="10" />
        <dynamics damping="0.1" friction="0.2"/>
    </joint>

    <link name="RL_foot">
        <inertial>
            <origin xyz="0 0 0" rpy="0 0 0" />
            <mass value="0.01"/>
            <inertia ixx="1e-5" ixy="0" ixz="0" iyy="1e-5" iyz="0" izz="1e-5"/>
        </inertial>
        <visual>
            <geometry><mesh filename="package://meshes/RL_foot.STL" /></geometry>
        </visual>
        <collision>
            <origin xyz="0 0 0" rpy="0 0 0"/>
            <geometry><sphere radius="0.021"/></geometry>
        </collision>
    </link>
    <joint name="RL_foot_joint" type="fixed" dont_collapse="true">
        <origin xyz="0 0 -0.214" rpy="0 0 0" />
        <parent link="RL_calf" />
        <child link="RL_foot" />
    </joint>

</robot>
